OKRA_VALIDATION CAUGHT IDENTIFY USER ERROR: 'firstDname'
Traceback (most recent call last):
  File "/Users/pygod/python_projects/payskul/core/main.py", line 39, in validate_update_user_status
    first_name = identity["firstDname"]
                 ~~~~~~~~^^^^^^^^^^^^^^
KeyError: 'firstDname'
OKRA_VALIDATION CAUGHT IDENTIFY USER ERROR: duplicate key value violates unique constraint "account_okralinkeduser_user_id_key"
DETAIL:  Key (user_id)=(120) already exists.
Traceback (most recent call last):
  File "/Users/pygod/python_projects/payskul/env/lib/python3.11/site-packages/django/db/models/query.py", line 928, in get_or_create
    return self.get(**kwargs), False
           ^^^^^^^^^^^^^^^^^^
  File "/Users/pygod/python_projects/payskul/env/lib/python3.11/site-packages/django/db/models/query.py", line 650, in get
    raise self.model.DoesNotExist(
account.models.OkraLinkedUser.DoesNotExist: OkraLinkedUser matching query does not exist.

During handling of the above exception, another exception occurred:

Traceback (most recent call last):
  File "/Users/pygod/python_projects/payskul/env/lib/python3.11/site-packages/django/db/backends/utils.py", line 89, in _execute
    return self.cursor.execute(sql, params)
           ^^^^^^^^^^^^^^^^^^^^^^^^^^^^^^^^
psycopg2.errors.UniqueViolation: duplicate key value violates unique constraint "account_okralinkeduser_user_id_key"
DETAIL:  Key (user_id)=(120) already exists.


The above exception was the direct cause of the following exception:

Traceback (most recent call last):
  File "/Users/pygod/python_projects/payskul/core/main.py", line 61, in validate_update_user_status
    obj,  created = OkraLinkedUser.objects.get_or_create(**self._to_save)
                    ^^^^^^^^^^^^^^^^^^^^^^^^^^^^^^^^^^^^^^^^^^^^^^^^^^^^^
  File "/Users/pygod/python_projects/payskul/env/lib/python3.11/site-packages/django/db/models/manager.py", line 85, in manager_method
    return getattr(self.get_queryset(), name)(*args, **kwargs)
           ^^^^^^^^^^^^^^^^^^^^^^^^^^^^^^^^^^^^^^^^^^^^^^^^^^^
  File "/Users/pygod/python_projects/payskul/env/lib/python3.11/site-packages/django/db/models/query.py", line 935, in get_or_create
    return self.create(**params), True
           ^^^^^^^^^^^^^^^^^^^^^
  File "/Users/pygod/python_projects/payskul/env/lib/python3.11/site-packages/django/db/models/query.py", line 671, in create
    obj.save(force_insert=True, using=self.db)
  File "/Users/pygod/python_projects/payskul/env/lib/python3.11/site-packages/django/db/models/base.py", line 812, in save
    self.save_base(
  File "/Users/pygod/python_projects/payskul/env/lib/python3.11/site-packages/django/db/models/base.py", line 863, in save_base
    updated = self._save_table(
              ^^^^^^^^^^^^^^^^^
  File "/Users/pygod/python_projects/payskul/env/lib/python3.11/site-packages/django/db/models/base.py", line 1006, in _save_table
    results = self._do_insert(
              ^^^^^^^^^^^^^^^^
  File "/Users/pygod/python_projects/payskul/env/lib/python3.11/site-packages/django/db/models/base.py", line 1047, in _do_insert
    return manager._insert(
           ^^^^^^^^^^^^^^^^
  File "/Users/pygod/python_projects/payskul/env/lib/python3.11/site-packages/django/db/models/manager.py", line 85, in manager_method
    return getattr(self.get_queryset(), name)(*args, **kwargs)
           ^^^^^^^^^^^^^^^^^^^^^^^^^^^^^^^^^^^^^^^^^^^^^^^^^^^
  File "/Users/pygod/python_projects/payskul/env/lib/python3.11/site-packages/django/db/models/query.py", line 1790, in _insert
    return query.get_compiler(using=using).execute_sql(returning_fields)
           ^^^^^^^^^^^^^^^^^^^^^^^^^^^^^^^^^^^^^^^^^^^^^^^^^^^^^^^^^^^^^
  File "/Users/pygod/python_projects/payskul/env/lib/python3.11/site-packages/django/db/models/sql/compiler.py", line 1660, in execute_sql
    cursor.execute(sql, params)
  File "/Users/pygod/python_projects/payskul/env/lib/python3.11/site-packages/django/db/backends/utils.py", line 103, in execute
    return super().execute(sql, params)
           ^^^^^^^^^^^^^^^^^^^^^^^^^^^^
  File "/Users/pygod/python_projects/payskul/env/lib/python3.11/site-packages/django/db/backends/utils.py", line 67, in execute
    return self._execute_with_wrappers(
           ^^^^^^^^^^^^^^^^^^^^^^^^^^^^
  File "/Users/pygod/python_projects/payskul/env/lib/python3.11/site-packages/django/db/backends/utils.py", line 80, in _execute_with_wrappers
    return executor(sql, params, many, context)
           ^^^^^^^^^^^^^^^^^^^^^^^^^^^^^^^^^^^^
  File "/Users/pygod/python_projects/payskul/env/lib/python3.11/site-packages/django/db/backends/utils.py", line 84, in _execute
    with self.db.wrap_database_errors:
  File "/Users/pygod/python_projects/payskul/env/lib/python3.11/site-packages/django/db/utils.py", line 91, in __exit__
    raise dj_exc_value.with_traceback(traceback) from exc_value
  File "/Users/pygod/python_projects/payskul/env/lib/python3.11/site-packages/django/db/backends/utils.py", line 89, in _execute
    return self.cursor.execute(sql, params)
           ^^^^^^^^^^^^^^^^^^^^^^^^^^^^^^^^
django.db.utils.IntegrityError: duplicate key value violates unique constraint "account_okralinkeduser_user_id_key"
DETAIL:  Key (user_id)=(120) already exists.

New user created: {'customer_id': '647b92b01519bc002f0c00be', 'registered_record': '647bda64e3226c002ef77012', 'registered_bank_id': '5d6fe57a4099cc4b210bbeb3', 'user': <User: okra_tester>, 'income_accounts': '5ef9050ce017d657c43e7a90:5ef9050ce017d657c43e7a90', 'income_banks': '5d6fe57a4099cc4b210bbeb7:5d6fe57a4099cc4b210bbeb7', 'avg_income': 1213164.5, 'initial_limit': 1061518.9375}
Failed to get incomE: User has no profile.
Internal Server Error: /core/get-limit/
Traceback (most recent call last):
  File "/Users/pygod/python_projects/payskul/core/utils.py", line 199, in update_customer_income_data
    profile = user.profile
              ^^^^^^^^^^^^
  File "/Users/pygod/python_projects/payskul/env/lib/python3.11/site-packages/django/db/models/fields/related_descriptors.py", line 461, in __get__
    raise self.RelatedObjectDoesNotExist(
django.contrib.auth.models.User.profile.RelatedObjectDoesNotExist: User has no profile.

During handling of the above exception, another exception occurred:

Traceback (most recent call last):
  File "/Users/pygod/python_projects/payskul/env/lib/python3.11/site-packages/django/core/handlers/exception.py", line 55, in inner
    response = get_response(request)
               ^^^^^^^^^^^^^^^^^^^^^
  File "/Users/pygod/python_projects/payskul/env/lib/python3.11/site-packages/django/core/handlers/base.py", line 197, in _get_response
    response = wrapped_callback(request, *callback_args, **callback_kwargs)
               ^^^^^^^^^^^^^^^^^^^^^^^^^^^^^^^^^^^^^^^^^^^^^^^^^^^^^^^^^^^^
  File "/Users/pygod/python_projects/payskul/env/lib/python3.11/site-packages/django/views/decorators/csrf.py", line 54, in wrapped_view
    return view_func(*args, **kwargs)
           ^^^^^^^^^^^^^^^^^^^^^^^^^^
  File "/Users/pygod/python_projects/payskul/env/lib/python3.11/site-packages/django/views/generic/base.py", line 103, in view
    return self.dispatch(request, *args, **kwargs)
           ^^^^^^^^^^^^^^^^^^^^^^^^^^^^^^^^^^^^^^^
  File "/Users/pygod/python_projects/payskul/env/lib/python3.11/site-packages/rest_framework/views.py", line 509, in dispatch
    response = self.handle_exception(exc)
               ^^^^^^^^^^^^^^^^^^^^^^^^^^
  File "/Users/pygod/python_projects/payskul/env/lib/python3.11/site-packages/rest_framework/views.py", line 469, in handle_exception
    self.raise_uncaught_exception(exc)
  File "/Users/pygod/python_projects/payskul/env/lib/python3.11/site-packages/rest_framework/views.py", line 480, in raise_uncaught_exception
    raise exc
  File "/Users/pygod/python_projects/payskul/env/lib/python3.11/site-packages/rest_framework/views.py", line 506, in dispatch
    response = handler(request, *args, **kwargs)
               ^^^^^^^^^^^^^^^^^^^^^^^^^^^^^^^^^
  File "/Users/pygod/python_projects/payskul/env/lib/python3.11/site-packages/rest_framework/decorators.py", line 50, in handler
    return func(*args, **kwargs)
           ^^^^^^^^^^^^^^^^^^^^^
  File "/Users/pygod/python_projects/payskul/core/views_v1.py", line 155, in update_client_income_status
    data = Okra.update_customer_income_data(user, "647e179b1519bc002f0d27e1")
           ^^^^^^^^^^^^^^^^^^^^^^^^^^^^^^^^^^^^^^^^^^^^^^^^^^^^^^^^^^^^^^^^^^
  File "/Users/pygod/python_projects/payskul/core/utils.py", line 224, in update_customer_income_data
    self._send_mail("Failed to get income:", e)
TypeError: Okra._send_mail() missing 1 required positional argument: 'error'
"GET /core/get-limit/ HTTP/1.1" 500 111858
Failed to get incomE: Okra._get_processed_income() missing 1 required positional argument: 'customerId'
Internal Server Error: /core/get-limit/
Traceback (most recent call last):
  File "/Users/pygod/python_projects/payskul/core/utils.py", line 201, in update_customer_income_data
    income_data = self._get_processed_income(customerId)
                  ^^^^^^^^^^^^^^^^^^^^^^^^^^^^^^^^^^^^^^
TypeError: Okra._get_processed_income() missing 1 required positional argument: 'customerId'

During handling of the above exception, another exception occurred:

Traceback (most recent call last):
  File "/Users/pygod/python_projects/payskul/env/lib/python3.11/site-packages/django/core/handlers/exception.py", line 55, in inner
    response = get_response(request)
               ^^^^^^^^^^^^^^^^^^^^^
  File "/Users/pygod/python_projects/payskul/env/lib/python3.11/site-packages/django/core/handlers/base.py", line 197, in _get_response
    response = wrapped_callback(request, *callback_args, **callback_kwargs)
               ^^^^^^^^^^^^^^^^^^^^^^^^^^^^^^^^^^^^^^^^^^^^^^^^^^^^^^^^^^^^
  File "/Users/pygod/python_projects/payskul/env/lib/python3.11/site-packages/django/views/decorators/csrf.py", line 54, in wrapped_view
    return view_func(*args, **kwargs)
           ^^^^^^^^^^^^^^^^^^^^^^^^^^
  File "/Users/pygod/python_projects/payskul/env/lib/python3.11/site-packages/django/views/generic/base.py", line 103, in view
    return self.dispatch(request, *args, **kwargs)
           ^^^^^^^^^^^^^^^^^^^^^^^^^^^^^^^^^^^^^^^
  File "/Users/pygod/python_projects/payskul/env/lib/python3.11/site-packages/rest_framework/views.py", line 509, in dispatch
    response = self.handle_exception(exc)
               ^^^^^^^^^^^^^^^^^^^^^^^^^^
  File "/Users/pygod/python_projects/payskul/env/lib/python3.11/site-packages/rest_framework/views.py", line 469, in handle_exception
    self.raise_uncaught_exception(exc)
  File "/Users/pygod/python_projects/payskul/env/lib/python3.11/site-packages/rest_framework/views.py", line 480, in raise_uncaught_exception
    raise exc
  File "/Users/pygod/python_projects/payskul/env/lib/python3.11/site-packages/rest_framework/views.py", line 506, in dispatch
    response = handler(request, *args, **kwargs)
               ^^^^^^^^^^^^^^^^^^^^^^^^^^^^^^^^^
  File "/Users/pygod/python_projects/payskul/env/lib/python3.11/site-packages/rest_framework/decorators.py", line 50, in handler
    return func(*args, **kwargs)
           ^^^^^^^^^^^^^^^^^^^^^
  File "/Users/pygod/python_projects/payskul/core/views_v1.py", line 155, in update_client_income_status
    data = Okra.update_customer_income_data(user, "647e179b1519bc002f0d27e1")
           ^^^^^^^^^^^^^^^^^^^^^^^^^^^^^^^^^^^^^^^^^^^^^^^^^^^^^^^^^^^^^^^^^^
  File "/Users/pygod/python_projects/payskul/core/utils.py", line 224, in update_customer_income_data
    self._send_mail("Failed to get income:", e)
TypeError: Okra._send_mail() missing 1 required positional argument: 'error'
"GET /core/get-limit/ HTTP/1.1" 500 107897
Failed to get incomE: Okra._get_processed_income() missing 1 required positional argument: 'customerId'
Internal Server Error: /core/get-limit/
Traceback (most recent call last):
  File "/Users/pygod/python_projects/payskul/core/utils.py", line 201, in update_customer_income_data
    income_data = self._get_processed_income(customerId)
                  ^^^^^^^^^^^^^^^^^^^^^^^^^^^^^^^^^^^^^^
TypeError: Okra._get_processed_income() missing 1 required positional argument: 'customerId'

During handling of the above exception, another exception occurred:

Traceback (most recent call last):
  File "/Users/pygod/python_projects/payskul/env/lib/python3.11/site-packages/django/core/handlers/exception.py", line 55, in inner
    response = get_response(request)
               ^^^^^^^^^^^^^^^^^^^^^
  File "/Users/pygod/python_projects/payskul/env/lib/python3.11/site-packages/django/core/handlers/base.py", line 197, in _get_response
    response = wrapped_callback(request, *callback_args, **callback_kwargs)
               ^^^^^^^^^^^^^^^^^^^^^^^^^^^^^^^^^^^^^^^^^^^^^^^^^^^^^^^^^^^^
  File "/Users/pygod/python_projects/payskul/env/lib/python3.11/site-packages/django/views/decorators/csrf.py", line 54, in wrapped_view
    return view_func(*args, **kwargs)
           ^^^^^^^^^^^^^^^^^^^^^^^^^^
  File "/Users/pygod/python_projects/payskul/env/lib/python3.11/site-packages/django/views/generic/base.py", line 103, in view
    return self.dispatch(request, *args, **kwargs)
           ^^^^^^^^^^^^^^^^^^^^^^^^^^^^^^^^^^^^^^^
  File "/Users/pygod/python_projects/payskul/env/lib/python3.11/site-packages/rest_framework/views.py", line 509, in dispatch
    response = self.handle_exception(exc)
               ^^^^^^^^^^^^^^^^^^^^^^^^^^
  File "/Users/pygod/python_projects/payskul/env/lib/python3.11/site-packages/rest_framework/views.py", line 469, in handle_exception
    self.raise_uncaught_exception(exc)
  File "/Users/pygod/python_projects/payskul/env/lib/python3.11/site-packages/rest_framework/views.py", line 480, in raise_uncaught_exception
    raise exc
  File "/Users/pygod/python_projects/payskul/env/lib/python3.11/site-packages/rest_framework/views.py", line 506, in dispatch
    response = handler(request, *args, **kwargs)
               ^^^^^^^^^^^^^^^^^^^^^^^^^^^^^^^^^
  File "/Users/pygod/python_projects/payskul/env/lib/python3.11/site-packages/rest_framework/decorators.py", line 50, in handler
    return func(*args, **kwargs)
           ^^^^^^^^^^^^^^^^^^^^^
  File "/Users/pygod/python_projects/payskul/core/views_v1.py", line 155, in update_client_income_status
    data = Okra.update_customer_income_data(user, "647e179b1519bc002f0d27e1")
           ^^^^^^^^^^^^^^^^^^^^^^^^^^^^^^^^^^^^^^^^^^^^^^^^^^^^^^^^^^^^^^^^^^
  File "/Users/pygod/python_projects/payskul/core/utils.py", line 224, in update_customer_income_data
    self._send_mail("Failed to get income:", e)
TypeError: Okra._send_mail() missing 1 required positional argument: 'error'
"GET /core/get-limit/ HTTP/1.1" 500 107897
Failed to get incomE: Okra._get_processed_income() missing 1 required positional argument: 'customerId'
Internal Server Error: /core/get-limit/
Traceback (most recent call last):
  File "/Users/pygod/python_projects/payskul/core/utils.py", line 201, in update_customer_income_data
    income_data = self._get_processed_income(customerId)
                  ^^^^^^^^^^^^^^^^^^^^^^^^^^^^^^^^^^^^^^
TypeError: Okra._get_processed_income() missing 1 required positional argument: 'customerId'

During handling of the above exception, another exception occurred:

Traceback (most recent call last):
  File "/Users/pygod/python_projects/payskul/env/lib/python3.11/site-packages/django/core/handlers/exception.py", line 55, in inner
    response = get_response(request)
               ^^^^^^^^^^^^^^^^^^^^^
  File "/Users/pygod/python_projects/payskul/env/lib/python3.11/site-packages/django/core/handlers/base.py", line 197, in _get_response
    response = wrapped_callback(request, *callback_args, **callback_kwargs)
               ^^^^^^^^^^^^^^^^^^^^^^^^^^^^^^^^^^^^^^^^^^^^^^^^^^^^^^^^^^^^
  File "/Users/pygod/python_projects/payskul/env/lib/python3.11/site-packages/django/views/decorators/csrf.py", line 54, in wrapped_view
    return view_func(*args, **kwargs)
           ^^^^^^^^^^^^^^^^^^^^^^^^^^
  File "/Users/pygod/python_projects/payskul/env/lib/python3.11/site-packages/django/views/generic/base.py", line 103, in view
    return self.dispatch(request, *args, **kwargs)
           ^^^^^^^^^^^^^^^^^^^^^^^^^^^^^^^^^^^^^^^
  File "/Users/pygod/python_projects/payskul/env/lib/python3.11/site-packages/rest_framework/views.py", line 509, in dispatch
    response = self.handle_exception(exc)
               ^^^^^^^^^^^^^^^^^^^^^^^^^^
  File "/Users/pygod/python_projects/payskul/env/lib/python3.11/site-packages/rest_framework/views.py", line 469, in handle_exception
    self.raise_uncaught_exception(exc)
  File "/Users/pygod/python_projects/payskul/env/lib/python3.11/site-packages/rest_framework/views.py", line 480, in raise_uncaught_exception
    raise exc
  File "/Users/pygod/python_projects/payskul/env/lib/python3.11/site-packages/rest_framework/views.py", line 506, in dispatch
    response = handler(request, *args, **kwargs)
               ^^^^^^^^^^^^^^^^^^^^^^^^^^^^^^^^^
  File "/Users/pygod/python_projects/payskul/env/lib/python3.11/site-packages/rest_framework/decorators.py", line 50, in handler
    return func(*args, **kwargs)
           ^^^^^^^^^^^^^^^^^^^^^
  File "/Users/pygod/python_projects/payskul/core/views_v1.py", line 155, in update_client_income_status
    data = Okra.update_customer_income_data(user, "647e179b1519bc002f0d27e1")
           ^^^^^^^^^^^^^^^^^^^^^^^^^^^^^^^^^^^^^^^^^^^^^^^^^^^^^^^^^^^^^^^^^^
  File "/Users/pygod/python_projects/payskul/core/utils.py", line 224, in update_customer_income_data
    self._send_mail("Failed to get income:", error=e)
TypeError: Okra._send_mail() missing 1 required positional argument: 'message'
"GET /core/get-limit/ HTTP/1.1" 500 107921
Failed to get incomE: Okra._get_processed_income() missing 1 required positional argument: 'customerId'
Internal Server Error: /core/get-limit/
Traceback (most recent call last):
  File "/Users/pygod/python_projects/payskul/core/utils.py", line 201, in update_customer_income_data
    income_data = cls._get_processed_income(customerId)
                  ^^^^^^^^^^^^^^^^^^^^^^^^^^^^^^^^^^^^^
TypeError: Okra._get_processed_income() missing 1 required positional argument: 'customerId'

During handling of the above exception, another exception occurred:

Traceback (most recent call last):
  File "/Users/pygod/python_projects/payskul/env/lib/python3.11/site-packages/django/core/handlers/exception.py", line 55, in inner
    response = get_response(request)
               ^^^^^^^^^^^^^^^^^^^^^
  File "/Users/pygod/python_projects/payskul/env/lib/python3.11/site-packages/django/core/handlers/base.py", line 197, in _get_response
    response = wrapped_callback(request, *callback_args, **callback_kwargs)
               ^^^^^^^^^^^^^^^^^^^^^^^^^^^^^^^^^^^^^^^^^^^^^^^^^^^^^^^^^^^^
  File "/Users/pygod/python_projects/payskul/env/lib/python3.11/site-packages/django/views/decorators/csrf.py", line 54, in wrapped_view
    return view_func(*args, **kwargs)
           ^^^^^^^^^^^^^^^^^^^^^^^^^^
  File "/Users/pygod/python_projects/payskul/env/lib/python3.11/site-packages/django/views/generic/base.py", line 103, in view
    return self.dispatch(request, *args, **kwargs)
           ^^^^^^^^^^^^^^^^^^^^^^^^^^^^^^^^^^^^^^^
  File "/Users/pygod/python_projects/payskul/env/lib/python3.11/site-packages/rest_framework/views.py", line 509, in dispatch
    response = self.handle_exception(exc)
               ^^^^^^^^^^^^^^^^^^^^^^^^^^
  File "/Users/pygod/python_projects/payskul/env/lib/python3.11/site-packages/rest_framework/views.py", line 469, in handle_exception
    self.raise_uncaught_exception(exc)
  File "/Users/pygod/python_projects/payskul/env/lib/python3.11/site-packages/rest_framework/views.py", line 480, in raise_uncaught_exception
    raise exc
  File "/Users/pygod/python_projects/payskul/env/lib/python3.11/site-packages/rest_framework/views.py", line 506, in dispatch
    response = handler(request, *args, **kwargs)
               ^^^^^^^^^^^^^^^^^^^^^^^^^^^^^^^^^
  File "/Users/pygod/python_projects/payskul/env/lib/python3.11/site-packages/rest_framework/decorators.py", line 50, in handler
    return func(*args, **kwargs)
           ^^^^^^^^^^^^^^^^^^^^^
  File "/Users/pygod/python_projects/payskul/core/views_v1.py", line 155, in update_client_income_status
    data = Okra.update_customer_income_data(user, "647e179b1519bc002f0d27e1")
           ^^^^^^^^^^^^^^^^^^^^^^^^^^^^^^^^^^^^^^^^^^^^^^^^^^^^^^^^^^^^^^^^^^
  File "/Users/pygod/python_projects/payskul/core/utils.py", line 224, in update_customer_income_data
    cls._send_mail("Failed to get income:", error=e)
TypeError: Okra._send_mail() missing 1 required positional argument: 'message'
"GET /core/get-limit/ HTTP/1.1" 500 107905
Internal Server Error: /
Traceback (most recent call last):
  File "/Users/pygod/python_projects/payskul/env/lib/python3.11/site-packages/django/core/handlers/exception.py", line 55, in inner
    response = get_response(request)
               ^^^^^^^^^^^^^^^^^^^^^
  File "/Users/pygod/python_projects/payskul/env/lib/python3.11/site-packages/django/core/handlers/base.py", line 197, in _get_response
    response = wrapped_callback(request, *callback_args, **callback_kwargs)
               ^^^^^^^^^^^^^^^^^^^^^^^^^^^^^^^^^^^^^^^^^^^^^^^^^^^^^^^^^^^^
  File "/Users/pygod/python_projects/payskul/apiv1/views.py", line 52, in home
    data = Okra.validate_update_user_status(payload=payload)
           ^^^^^^^^^^^^^^^^^^^^^^^^^^^^^^^^^^^^^^^^^^^^^^^^^
  File "/Users/pygod/python_projects/payskul/core/utils.py", line 144, in validate_update_user_status
    if self._is_valid_auth_success(data):
       ^^^^^^^^^^^^^^^^^^^^^^^^^^^^^^^^^
TypeError: Okra._is_valid_auth_success() missing 1 required positional argument: 'data'
"GET / HTTP/1.1" 500 75729
Internal Server Error: /
Traceback (most recent call last):
  File "/Users/pygod/python_projects/payskul/env/lib/python3.11/site-packages/django/core/handlers/exception.py", line 55, in inner
    response = get_response(request)
               ^^^^^^^^^^^^^^^^^^^^^
  File "/Users/pygod/python_projects/payskul/env/lib/python3.11/site-packages/django/core/handlers/base.py", line 197, in _get_response
    response = wrapped_callback(request, *callback_args, **callback_kwargs)
               ^^^^^^^^^^^^^^^^^^^^^^^^^^^^^^^^^^^^^^^^^^^^^^^^^^^^^^^^^^^^
  File "/Users/pygod/python_projects/payskul/apiv1/views.py", line 53, in home
    data = ok.validate_update_user_status(payload=payload)
           ^^^^^^^^^^^^^^^^^^^^^^^^^^^^^^^^^^^^^^^^^^^^^^^
  File "/Users/pygod/python_projects/payskul/core/utils.py", line 144, in validate_update_user_status
    if self._is_valid_auth_success(data):
       ^^^^^^^^^^^^^^^^^^^^^^^^^^^^^^^^^
TypeError: Okra._is_valid_auth_success() missing 1 required positional argument: 'data'
"GET / HTTP/1.1" 500 75935
Internal Server Error: /
Traceback (most recent call last):
  File "/Users/pygod/python_projects/payskul/env/lib/python3.11/site-packages/django/core/handlers/exception.py", line 55, in inner
    response = get_response(request)
               ^^^^^^^^^^^^^^^^^^^^^
  File "/Users/pygod/python_projects/payskul/env/lib/python3.11/site-packages/django/core/handlers/base.py", line 197, in _get_response
    response = wrapped_callback(request, *callback_args, **callback_kwargs)
               ^^^^^^^^^^^^^^^^^^^^^^^^^^^^^^^^^^^^^^^^^^^^^^^^^^^^^^^^^^^^
  File "/Users/pygod/python_projects/payskul/apiv1/views.py", line 53, in home
    data = ok.validate_update_user_status(payload=payload)
           ^^^^^^^^^^^^^^^^^^^^^^^^^^^^^^^^^^^^^^^^^^^^^^^
  File "/Users/pygod/python_projects/payskul/core/utils.py", line 144, in validate_update_user_status
    if self._is_valid_auth_success(data):
       ^^^^^^^^^^^^^^^^^^^^^^^^^^^^^^^^^
TypeError: Okra._is_valid_auth_success() missing 1 required positional argument: 'data'
"GET / HTTP/1.1" 500 75935
OKRA_VALIDATION CAUGHT IDENTIFY USER ERROR: 'Okra' object has no attribute 'IDENTITY_URL'
Traceback (most recent call last):
  File "/Users/pygod/python_projects/payskul/core/utils.py", line 151, in validate_update_user_status
    identity_data = self._get_identity_details(customerId)
                    ^^^^^^^^^^^^^^^^^^^^^^^^^^^^^^^^^^^^^^
  File "/Users/pygod/python_projects/payskul/core/utils.py", line 245, in _get_identity_details
    identity_response = requests.post(url=self.IDENTITY_URL, json=id_payload, headers=self._HEADERS)
                                          ^^^^^^^^^^^^^^^^^
AttributeError: 'Okra' object has no attribute 'IDENTITY_URL'
Internal Server Error: /
Traceback (most recent call last):
  File "/Users/pygod/python_projects/payskul/env/lib/python3.11/site-packages/django/core/handlers/exception.py", line 55, in inner
    response = get_response(request)
               ^^^^^^^^^^^^^^^^^^^^^
  File "/Users/pygod/python_projects/payskul/env/lib/python3.11/site-packages/django/core/handlers/base.py", line 197, in _get_response
    response = wrapped_callback(request, *callback_args, **callback_kwargs)
               ^^^^^^^^^^^^^^^^^^^^^^^^^^^^^^^^^^^^^^^^^^^^^^^^^^^^^^^^^^^^
  File "/Users/pygod/python_projects/payskul/apiv1/views.py", line 53, in home
    data = ok.validate_update_user_status(payload=payload)
           ^^^^^^^^^^^^^^^^^^^^^^^^^^^^^^^^^^^^^^^^^^^^^^^
  File "/Users/pygod/python_projects/payskul/core/utils.py", line 145, in validate_update_user_status
    if self._is_valid_auth_success(data):
       ^^^^^^^^^^^^^^^^^^^^^^^^^^^^^^^^^
TypeError: Okra._is_valid_auth_success() missing 1 required positional argument: 'data'
"GET / HTTP/1.1" 500 75932
Internal Server Error: /
Traceback (most recent call last):
  File "/Users/pygod/python_projects/payskul/env/lib/python3.11/site-packages/django/core/handlers/exception.py", line 55, in inner
    response = get_response(request)
               ^^^^^^^^^^^^^^^^^^^^^
  File "/Users/pygod/python_projects/payskul/env/lib/python3.11/site-packages/django/core/handlers/base.py", line 197, in _get_response
    response = wrapped_callback(request, *callback_args, **callback_kwargs)
               ^^^^^^^^^^^^^^^^^^^^^^^^^^^^^^^^^^^^^^^^^^^^^^^^^^^^^^^^^^^^
  File "/Users/pygod/python_projects/payskul/apiv1/views.py", line 53, in home
    data = ok.validate_update_user_status(payload=payload)
           ^^^^^^^^^^^^^^^^^^^^^^^^^^^^^^^^^^^^^^^^^^^^^^^
  File "/Users/pygod/python_projects/payskul/core/utils.py", line 145, in validate_update_user_status
    if self._is_valid_auth_success(data):
       ^^^^^^^^^^^^^^^^^^^^^^^^^^^^^^^^^
TypeError: Okra._is_valid_auth_success() missing 1 required positional argument: 'data'
"GET / HTTP/1.1" 500 75932
Internal Server Error: /
Traceback (most recent call last):
  File "/Users/pygod/python_projects/payskul/env/lib/python3.11/site-packages/django/core/handlers/exception.py", line 55, in inner
    response = get_response(request)
               ^^^^^^^^^^^^^^^^^^^^^
  File "/Users/pygod/python_projects/payskul/env/lib/python3.11/site-packages/django/core/handlers/base.py", line 197, in _get_response
    response = wrapped_callback(request, *callback_args, **callback_kwargs)
               ^^^^^^^^^^^^^^^^^^^^^^^^^^^^^^^^^^^^^^^^^^^^^^^^^^^^^^^^^^^^
  File "/Users/pygod/python_projects/payskul/apiv1/views.py", line 53, in home
    data = ok.validate_update_user_status(payload=payload)
           ^^^^^^^^^^^^^^^^^^^^^^^^^^^^^^^^^^^^^^^^^^^^^^^
  File "/Users/pygod/python_projects/payskul/core/utils.py", line 145, in validate_update_user_status
    if self._is_valid_auth_success(data):
       ^^^^^^^^^^^^^^^^^^^^^^^^^^^^^^^^^
TypeError: Okra._is_valid_auth_success() missing 1 required positional argument: 'data'
"GET / HTTP/1.1" 500 75932
OKRA_VALIDATION CAUGHT IDENTIFY USER ERROR: 'Okra' object has no attribute '_IDENTITY_URL'
Traceback (most recent call last):
  File "/Users/pygod/python_projects/payskul/core/utils.py", line 151, in validate_update_user_status
    identity_data = self._get_identity_details(customerId)
                    ^^^^^^^^^^^^^^^^^^^^^^^^^^^^^^^^^^^^^^
  File "/Users/pygod/python_projects/payskul/core/utils.py", line 245, in _get_identity_details
    identity_response = requests.post(url=self._IDENTITY_URL, json=id_payload, headers=self._HEADERS)
                                          ^^^^^^^^^^^^^^^^^^
AttributeError: 'Okra' object has no attribute '_IDENTITY_URL'
Send mail error: (535, b'Incorrect authentication data')
Failed to get income
{'status': 'error', 'message': 'Invalid token', 'data': None}
Failed to get income
{'status': 'error', 'message': 'Invalid token', 'data': None}
Failed to get income
{'status': 'error', 'message': 'Invalid token', 'data': None}
Failed to get incomE: HTTPSConnectionPool(host='api.okra.ng', port=443): Max retries exceeded with url: /v2/sandbox/income/process (Caused by NewConnectionError('<urllib3.connection.HTTPSConnection object at 0x103cf72d0>: Failed to establish a new connection: [Errno 8] nodename nor servname provided, or not known'))
Send mail error: [Errno 8] nodename nor servname provided, or not known
Failed to get income
{'status': 'error', 'message': 'Invalid token', 'data': None}
Failed to get income
{'status': 'error', 'message': 'Invalid token', 'data': None}
Failed to get income
{'status': 'error', 'message': 'Invalid token', 'data': None}
Failed to get income from OKRA(API): 'OkraLinkedUser' object has no attribute 'update'
Send mail error: (535, b'Incorrect authentication data')
Failed to get income from OKRA(API): 'OkraLinkedUser' object has no attribute 'update'
Failed to get income from OKRA(API): Model.save() got an unexpected keyword argument 'user'
New user created: {'user': <User: mercygreen>, 'income_accounts': '5ef9050ce017d657c43e7a90:5ef9050ce017d657c43e7a90', 'income_banks': '5d6fe57a4099cc4b210bbeb7:5d6fe57a4099cc4b210bbeb7', 'avg_income': 1329843.5, 'initial_limit': 1163613.0625}
Internal Server Error: /core/get-limit/
"GET /core/get-limit/ HTTP/1.1" 500 48
Internal Server Error: /core/get-banks/
Traceback (most recent call last):
  File "/Users/pygod/python_projects/payskul/env/lib/python3.11/site-packages/django/core/handlers/exception.py", line 55, in inner
    response = get_response(request)
               ^^^^^^^^^^^^^^^^^^^^^
  File "/Users/pygod/python_projects/payskul/env/lib/python3.11/site-packages/django/core/handlers/base.py", line 197, in _get_response
    response = wrapped_callback(request, *callback_args, **callback_kwargs)
               ^^^^^^^^^^^^^^^^^^^^^^^^^^^^^^^^^^^^^^^^^^^^^^^^^^^^^^^^^^^^
  File "/Users/pygod/python_projects/payskul/env/lib/python3.11/site-packages/django/views/decorators/csrf.py", line 54, in wrapped_view
    return view_func(*args, **kwargs)
           ^^^^^^^^^^^^^^^^^^^^^^^^^^
  File "/Users/pygod/python_projects/payskul/env/lib/python3.11/site-packages/django/views/generic/base.py", line 103, in view
    return self.dispatch(request, *args, **kwargs)
           ^^^^^^^^^^^^^^^^^^^^^^^^^^^^^^^^^^^^^^^
  File "/Users/pygod/python_projects/payskul/env/lib/python3.11/site-packages/rest_framework/views.py", line 509, in dispatch
    response = self.handle_exception(exc)
               ^^^^^^^^^^^^^^^^^^^^^^^^^^
  File "/Users/pygod/python_projects/payskul/env/lib/python3.11/site-packages/rest_framework/views.py", line 469, in handle_exception
    self.raise_uncaught_exception(exc)
  File "/Users/pygod/python_projects/payskul/env/lib/python3.11/site-packages/rest_framework/views.py", line 480, in raise_uncaught_exception
    raise exc
  File "/Users/pygod/python_projects/payskul/env/lib/python3.11/site-packages/rest_framework/views.py", line 506, in dispatch
    response = handler(request, *args, **kwargs)
               ^^^^^^^^^^^^^^^^^^^^^^^^^^^^^^^^^
  File "/Users/pygod/python_projects/payskul/env/lib/python3.11/site-packages/rest_framework/decorators.py", line 50, in handler
    return func(*args, **kwargs)
           ^^^^^^^^^^^^^^^^^^^^^
  File "/Users/pygod/python_projects/payskul/core/views_v1.py", line 134, in get_banks
    data = Okra.bank_list()
           ^^^^^^^^^^^^^^^^
TypeError: Okra.bank_list() missing 1 required positional argument: 'cls'
"GET /core/get-banks/ HTTP/1.1" 500 99596
Internal Server Error: /core/get-banks/
Traceback (most recent call last):
  File "/Users/pygod/python_projects/payskul/env/lib/python3.11/site-packages/django/core/handlers/exception.py", line 55, in inner
    response = get_response(request)
               ^^^^^^^^^^^^^^^^^^^^^
  File "/Users/pygod/python_projects/payskul/env/lib/python3.11/site-packages/django/core/handlers/base.py", line 197, in _get_response
    response = wrapped_callback(request, *callback_args, **callback_kwargs)
               ^^^^^^^^^^^^^^^^^^^^^^^^^^^^^^^^^^^^^^^^^^^^^^^^^^^^^^^^^^^^
  File "/Users/pygod/python_projects/payskul/env/lib/python3.11/site-packages/django/views/decorators/csrf.py", line 54, in wrapped_view
    return view_func(*args, **kwargs)
           ^^^^^^^^^^^^^^^^^^^^^^^^^^
  File "/Users/pygod/python_projects/payskul/env/lib/python3.11/site-packages/django/views/generic/base.py", line 103, in view
    return self.dispatch(request, *args, **kwargs)
           ^^^^^^^^^^^^^^^^^^^^^^^^^^^^^^^^^^^^^^^
  File "/Users/pygod/python_projects/payskul/env/lib/python3.11/site-packages/rest_framework/views.py", line 509, in dispatch
    response = self.handle_exception(exc)
               ^^^^^^^^^^^^^^^^^^^^^^^^^^
  File "/Users/pygod/python_projects/payskul/env/lib/python3.11/site-packages/rest_framework/views.py", line 469, in handle_exception
    self.raise_uncaught_exception(exc)
  File "/Users/pygod/python_projects/payskul/env/lib/python3.11/site-packages/rest_framework/views.py", line 480, in raise_uncaught_exception
    raise exc
  File "/Users/pygod/python_projects/payskul/env/lib/python3.11/site-packages/rest_framework/views.py", line 506, in dispatch
    response = handler(request, *args, **kwargs)
               ^^^^^^^^^^^^^^^^^^^^^^^^^^^^^^^^^
  File "/Users/pygod/python_projects/payskul/env/lib/python3.11/site-packages/rest_framework/decorators.py", line 50, in handler
    return func(*args, **kwargs)
           ^^^^^^^^^^^^^^^^^^^^^
  File "/Users/pygod/python_projects/payskul/core/views_v1.py", line 134, in get_banks
    data = Okra.bank_list()
           ^^^^^^^^^^^^^^^^
TypeError: Okra.bank_list() missing 1 required positional argument: 'cls'
"GET /core/get-banks/ HTTP/1.1" 500 99596
Internal Server Error: /account/login/
Traceback (most recent call last):
  File "/Users/pygod/python_projects/payskul/env/lib/python3.11/site-packages/django/core/handlers/exception.py", line 55, in inner
    response = get_response(request)
               ^^^^^^^^^^^^^^^^^^^^^
  File "/Users/pygod/python_projects/payskul/env/lib/python3.11/site-packages/django/core/handlers/base.py", line 197, in _get_response
    response = wrapped_callback(request, *callback_args, **callback_kwargs)
               ^^^^^^^^^^^^^^^^^^^^^^^^^^^^^^^^^^^^^^^^^^^^^^^^^^^^^^^^^^^^
  File "/Users/pygod/python_projects/payskul/env/lib/python3.11/site-packages/django/views/decorators/csrf.py", line 54, in wrapped_view
    return view_func(*args, **kwargs)
           ^^^^^^^^^^^^^^^^^^^^^^^^^^
  File "/Users/pygod/python_projects/payskul/env/lib/python3.11/site-packages/django/views/generic/base.py", line 103, in view
    return self.dispatch(request, *args, **kwargs)
           ^^^^^^^^^^^^^^^^^^^^^^^^^^^^^^^^^^^^^^^
  File "/Users/pygod/python_projects/payskul/env/lib/python3.11/site-packages/rest_framework/views.py", line 509, in dispatch
    response = self.handle_exception(exc)
               ^^^^^^^^^^^^^^^^^^^^^^^^^^
  File "/Users/pygod/python_projects/payskul/env/lib/python3.11/site-packages/rest_framework/views.py", line 469, in handle_exception
    self.raise_uncaught_exception(exc)
  File "/Users/pygod/python_projects/payskul/env/lib/python3.11/site-packages/rest_framework/views.py", line 480, in raise_uncaught_exception
    raise exc
  File "/Users/pygod/python_projects/payskul/env/lib/python3.11/site-packages/rest_framework/views.py", line 506, in dispatch
    response = handler(request, *args, **kwargs)
               ^^^^^^^^^^^^^^^^^^^^^^^^^^^^^^^^^
  File "/Users/pygod/python_projects/payskul/env/lib/python3.11/site-packages/django/views/decorators/csrf.py", line 54, in wrapped_view
    return view_func(*args, **kwargs)
           ^^^^^^^^^^^^^^^^^^^^^^^^^^
  File "/Users/pygod/python_projects/payskul/account/views_v1.py", line 172, in post
    profile = Profile.objects.get(user=user)
              ^^^^^^^^^^^^^^^^^^^^^^^^^^^^^^
  File "/Users/pygod/python_projects/payskul/env/lib/python3.11/site-packages/django/db/models/manager.py", line 85, in manager_method
    return getattr(self.get_queryset(), name)(*args, **kwargs)
           ^^^^^^^^^^^^^^^^^^^^^^^^^^^^^^^^^^^^^^^^^^^^^^^^^^^
  File "/Users/pygod/python_projects/payskul/env/lib/python3.11/site-packages/django/db/models/query.py", line 650, in get
    raise self.model.DoesNotExist(
account.models.Profile.DoesNotExist: Profile matching query does not exist.
"POST /account/login/ HTTP/1.1" 500 105906
Internal Server Error: /account/create-user/
Traceback (most recent call last):
  File "/Users/pygod/python_projects/payskul/env/lib/python3.11/site-packages/django/core/handlers/exception.py", line 55, in inner
    response = get_response(request)
               ^^^^^^^^^^^^^^^^^^^^^
  File "/Users/pygod/python_projects/payskul/env/lib/python3.11/site-packages/django/core/handlers/base.py", line 197, in _get_response
    response = wrapped_callback(request, *callback_args, **callback_kwargs)
               ^^^^^^^^^^^^^^^^^^^^^^^^^^^^^^^^^^^^^^^^^^^^^^^^^^^^^^^^^^^^
  File "/Users/pygod/python_projects/payskul/env/lib/python3.11/site-packages/django/views/decorators/csrf.py", line 54, in wrapped_view
    return view_func(*args, **kwargs)
           ^^^^^^^^^^^^^^^^^^^^^^^^^^
  File "/Users/pygod/python_projects/payskul/env/lib/python3.11/site-packages/django/views/decorators/csrf.py", line 54, in wrapped_view
    return view_func(*args, **kwargs)
           ^^^^^^^^^^^^^^^^^^^^^^^^^^
  File "/Users/pygod/python_projects/payskul/env/lib/python3.11/site-packages/django/views/generic/base.py", line 103, in view
    return self.dispatch(request, *args, **kwargs)
           ^^^^^^^^^^^^^^^^^^^^^^^^^^^^^^^^^^^^^^^
  File "/Users/pygod/python_projects/payskul/env/lib/python3.11/site-packages/rest_framework/views.py", line 509, in dispatch
    response = self.handle_exception(exc)
               ^^^^^^^^^^^^^^^^^^^^^^^^^^
  File "/Users/pygod/python_projects/payskul/env/lib/python3.11/site-packages/rest_framework/views.py", line 469, in handle_exception
    self.raise_uncaught_exception(exc)
  File "/Users/pygod/python_projects/payskul/env/lib/python3.11/site-packages/rest_framework/views.py", line 480, in raise_uncaught_exception
    raise exc
  File "/Users/pygod/python_projects/payskul/env/lib/python3.11/site-packages/rest_framework/views.py", line 506, in dispatch
    response = handler(request, *args, **kwargs)
               ^^^^^^^^^^^^^^^^^^^^^^^^^^^^^^^^^
  File "/Users/pygod/python_projects/payskul/env/lib/python3.11/site-packages/rest_framework/decorators.py", line 50, in handler
    return func(*args, **kwargs)
           ^^^^^^^^^^^^^^^^^^^^^
  File "/Users/pygod/python_projects/payskul/account/views_v1.py", line 115, in create_user
    token = UserAuthCodes.objects.get(id=data['id']).code
            ^^^^^^^^^^^^^^^^^^^^^^^^^^^^^^^^^^^^^^^^
  File "/Users/pygod/python_projects/payskul/env/lib/python3.11/site-packages/django/db/models/manager.py", line 85, in manager_method
    return getattr(self.get_queryset(), name)(*args, **kwargs)
           ^^^^^^^^^^^^^^^^^^^^^^^^^^^^^^^^^^^^^^^^^^^^^^^^^^^
  File "/Users/pygod/python_projects/payskul/env/lib/python3.11/site-packages/django/db/models/query.py", line 650, in get
    raise self.model.DoesNotExist(
account.models.UserAuthCodes.DoesNotExist: UserAuthCodes matching query does not exist.
"POST /account/create-user/ HTTP/1.1" 500 113160
Internal Server Error: /account/login/
Traceback (most recent call last):
  File "/Users/pygod/python_projects/payskul/env/lib/python3.11/site-packages/django/core/handlers/exception.py", line 55, in inner
    response = get_response(request)
               ^^^^^^^^^^^^^^^^^^^^^
  File "/Users/pygod/python_projects/payskul/env/lib/python3.11/site-packages/django/core/handlers/base.py", line 197, in _get_response
    response = wrapped_callback(request, *callback_args, **callback_kwargs)
               ^^^^^^^^^^^^^^^^^^^^^^^^^^^^^^^^^^^^^^^^^^^^^^^^^^^^^^^^^^^^
  File "/Users/pygod/python_projects/payskul/env/lib/python3.11/site-packages/django/views/decorators/csrf.py", line 54, in wrapped_view
    return view_func(*args, **kwargs)
           ^^^^^^^^^^^^^^^^^^^^^^^^^^
  File "/Users/pygod/python_projects/payskul/env/lib/python3.11/site-packages/django/views/generic/base.py", line 103, in view
    return self.dispatch(request, *args, **kwargs)
           ^^^^^^^^^^^^^^^^^^^^^^^^^^^^^^^^^^^^^^^
  File "/Users/pygod/python_projects/payskul/env/lib/python3.11/site-packages/rest_framework/views.py", line 509, in dispatch
    response = self.handle_exception(exc)
               ^^^^^^^^^^^^^^^^^^^^^^^^^^
  File "/Users/pygod/python_projects/payskul/env/lib/python3.11/site-packages/rest_framework/views.py", line 469, in handle_exception
    self.raise_uncaught_exception(exc)
  File "/Users/pygod/python_projects/payskul/env/lib/python3.11/site-packages/rest_framework/views.py", line 480, in raise_uncaught_exception
    raise exc
  File "/Users/pygod/python_projects/payskul/env/lib/python3.11/site-packages/rest_framework/views.py", line 506, in dispatch
    response = handler(request, *args, **kwargs)
               ^^^^^^^^^^^^^^^^^^^^^^^^^^^^^^^^^
  File "/Users/pygod/python_projects/payskul/env/lib/python3.11/site-packages/django/views/decorators/csrf.py", line 54, in wrapped_view
    return view_func(*args, **kwargs)
           ^^^^^^^^^^^^^^^^^^^^^^^^^^
  File "/Users/pygod/python_projects/payskul/account/views_v1.py", line 172, in post
    profile = Profile.objects.get(user=user)
              ^^^^^^^^^^^^^^^^^^^^^^^^^^^^^^
  File "/Users/pygod/python_projects/payskul/env/lib/python3.11/site-packages/django/db/models/manager.py", line 85, in manager_method
    return getattr(self.get_queryset(), name)(*args, **kwargs)
           ^^^^^^^^^^^^^^^^^^^^^^^^^^^^^^^^^^^^^^^^^^^^^^^^^^^
  File "/Users/pygod/python_projects/payskul/env/lib/python3.11/site-packages/django/db/models/query.py", line 650, in get
    raise self.model.DoesNotExist(
account.models.Profile.DoesNotExist: Profile matching query does not exist.
"POST /account/login/ HTTP/1.1" 500 105951
Internal Server Error: /account/create-user/
Traceback (most recent call last):
  File "/Users/pygod/python_projects/payskul/env/lib/python3.11/site-packages/django/core/handlers/exception.py", line 55, in inner
    response = get_response(request)
               ^^^^^^^^^^^^^^^^^^^^^
  File "/Users/pygod/python_projects/payskul/env/lib/python3.11/site-packages/django/core/handlers/base.py", line 197, in _get_response
    response = wrapped_callback(request, *callback_args, **callback_kwargs)
               ^^^^^^^^^^^^^^^^^^^^^^^^^^^^^^^^^^^^^^^^^^^^^^^^^^^^^^^^^^^^
  File "/Users/pygod/python_projects/payskul/env/lib/python3.11/site-packages/django/views/decorators/csrf.py", line 54, in wrapped_view
    return view_func(*args, **kwargs)
           ^^^^^^^^^^^^^^^^^^^^^^^^^^
  File "/Users/pygod/python_projects/payskul/env/lib/python3.11/site-packages/django/views/decorators/csrf.py", line 54, in wrapped_view
    return view_func(*args, **kwargs)
           ^^^^^^^^^^^^^^^^^^^^^^^^^^
  File "/Users/pygod/python_projects/payskul/env/lib/python3.11/site-packages/django/views/generic/base.py", line 103, in view
    return self.dispatch(request, *args, **kwargs)
           ^^^^^^^^^^^^^^^^^^^^^^^^^^^^^^^^^^^^^^^
  File "/Users/pygod/python_projects/payskul/env/lib/python3.11/site-packages/rest_framework/views.py", line 509, in dispatch
    response = self.handle_exception(exc)
               ^^^^^^^^^^^^^^^^^^^^^^^^^^
  File "/Users/pygod/python_projects/payskul/env/lib/python3.11/site-packages/rest_framework/views.py", line 469, in handle_exception
    self.raise_uncaught_exception(exc)
  File "/Users/pygod/python_projects/payskul/env/lib/python3.11/site-packages/rest_framework/views.py", line 480, in raise_uncaught_exception
    raise exc
  File "/Users/pygod/python_projects/payskul/env/lib/python3.11/site-packages/rest_framework/views.py", line 506, in dispatch
    response = handler(request, *args, **kwargs)
               ^^^^^^^^^^^^^^^^^^^^^^^^^^^^^^^^^
  File "/Users/pygod/python_projects/payskul/env/lib/python3.11/site-packages/rest_framework/decorators.py", line 50, in handler
    return func(*args, **kwargs)
           ^^^^^^^^^^^^^^^^^^^^^
  File "/Users/pygod/python_projects/payskul/account/views_v1.py", line 115, in create_user
    token = UserAuthCodes.objects.get(id=data['id']).code
            ^^^^^^^^^^^^^^^^^^^^^^^^^^^^^^^^^^^^^^^^
  File "/Users/pygod/python_projects/payskul/env/lib/python3.11/site-packages/django/db/models/manager.py", line 85, in manager_method
    return getattr(self.get_queryset(), name)(*args, **kwargs)
           ^^^^^^^^^^^^^^^^^^^^^^^^^^^^^^^^^^^^^^^^^^^^^^^^^^^
  File "/Users/pygod/python_projects/payskul/env/lib/python3.11/site-packages/django/db/models/query.py", line 650, in get
    raise self.model.DoesNotExist(
account.models.UserAuthCodes.DoesNotExist: UserAuthCodes matching query does not exist.
"POST /account/create-user/ HTTP/1.1" 500 113214
Internal Server Error: /account/login/
Traceback (most recent call last):
  File "/Users/pygod/python_projects/payskul/env/lib/python3.11/site-packages/django/core/handlers/exception.py", line 55, in inner
    response = get_response(request)
               ^^^^^^^^^^^^^^^^^^^^^
  File "/Users/pygod/python_projects/payskul/env/lib/python3.11/site-packages/django/core/handlers/base.py", line 197, in _get_response
    response = wrapped_callback(request, *callback_args, **callback_kwargs)
               ^^^^^^^^^^^^^^^^^^^^^^^^^^^^^^^^^^^^^^^^^^^^^^^^^^^^^^^^^^^^
  File "/Users/pygod/python_projects/payskul/env/lib/python3.11/site-packages/django/views/decorators/csrf.py", line 54, in wrapped_view
    return view_func(*args, **kwargs)
           ^^^^^^^^^^^^^^^^^^^^^^^^^^
  File "/Users/pygod/python_projects/payskul/env/lib/python3.11/site-packages/django/views/generic/base.py", line 103, in view
    return self.dispatch(request, *args, **kwargs)
           ^^^^^^^^^^^^^^^^^^^^^^^^^^^^^^^^^^^^^^^
  File "/Users/pygod/python_projects/payskul/env/lib/python3.11/site-packages/rest_framework/views.py", line 509, in dispatch
    response = self.handle_exception(exc)
               ^^^^^^^^^^^^^^^^^^^^^^^^^^
  File "/Users/pygod/python_projects/payskul/env/lib/python3.11/site-packages/rest_framework/views.py", line 469, in handle_exception
    self.raise_uncaught_exception(exc)
  File "/Users/pygod/python_projects/payskul/env/lib/python3.11/site-packages/rest_framework/views.py", line 480, in raise_uncaught_exception
    raise exc
  File "/Users/pygod/python_projects/payskul/env/lib/python3.11/site-packages/rest_framework/views.py", line 506, in dispatch
    response = handler(request, *args, **kwargs)
               ^^^^^^^^^^^^^^^^^^^^^^^^^^^^^^^^^
  File "/Users/pygod/python_projects/payskul/env/lib/python3.11/site-packages/django/views/decorators/csrf.py", line 54, in wrapped_view
    return view_func(*args, **kwargs)
           ^^^^^^^^^^^^^^^^^^^^^^^^^^
  File "/Users/pygod/python_projects/payskul/account/views_v1.py", line 178, in post
    "has_activae_loan": profile.has_activae_loan,
                        ^^^^^^^^^^^^^^^^^^^^^^^^
AttributeError: 'Profile' object has no attribute 'has_activae_loan'
"POST /account/login/ HTTP/1.1" 500 98771
Internal Server Error: /account/login/
Traceback (most recent call last):
  File "/Users/pygod/python_projects/payskul/env/lib/python3.11/site-packages/django/core/handlers/exception.py", line 55, in inner
    response = get_response(request)
               ^^^^^^^^^^^^^^^^^^^^^
  File "/Users/pygod/python_projects/payskul/env/lib/python3.11/site-packages/django/core/handlers/base.py", line 197, in _get_response
    response = wrapped_callback(request, *callback_args, **callback_kwargs)
               ^^^^^^^^^^^^^^^^^^^^^^^^^^^^^^^^^^^^^^^^^^^^^^^^^^^^^^^^^^^^
  File "/Users/pygod/python_projects/payskul/env/lib/python3.11/site-packages/django/views/decorators/csrf.py", line 54, in wrapped_view
    return view_func(*args, **kwargs)
           ^^^^^^^^^^^^^^^^^^^^^^^^^^
  File "/Users/pygod/python_projects/payskul/env/lib/python3.11/site-packages/django/views/generic/base.py", line 103, in view
    return self.dispatch(request, *args, **kwargs)
           ^^^^^^^^^^^^^^^^^^^^^^^^^^^^^^^^^^^^^^^
  File "/Users/pygod/python_projects/payskul/env/lib/python3.11/site-packages/rest_framework/views.py", line 509, in dispatch
    response = self.handle_exception(exc)
               ^^^^^^^^^^^^^^^^^^^^^^^^^^
  File "/Users/pygod/python_projects/payskul/env/lib/python3.11/site-packages/rest_framework/views.py", line 469, in handle_exception
    self.raise_uncaught_exception(exc)
  File "/Users/pygod/python_projects/payskul/env/lib/python3.11/site-packages/rest_framework/views.py", line 480, in raise_uncaught_exception
    raise exc
  File "/Users/pygod/python_projects/payskul/env/lib/python3.11/site-packages/rest_framework/views.py", line 506, in dispatch
    response = handler(request, *args, **kwargs)
               ^^^^^^^^^^^^^^^^^^^^^^^^^^^^^^^^^
  File "/Users/pygod/python_projects/payskul/env/lib/python3.11/site-packages/django/views/decorators/csrf.py", line 54, in wrapped_view
    return view_func(*args, **kwargs)
           ^^^^^^^^^^^^^^^^^^^^^^^^^^
  File "/Users/pygod/python_projects/payskul/account/views_v1.py", line 178, in post
    "has_activae_loan": profile.has_activate_loan,
                        ^^^^^^^^^^^^^^^^^^^^^^^^^
AttributeError: 'Profile' object has no attribute 'has_activate_loan'
"POST /account/login/ HTTP/1.1" 500 99261
